Workbook

Sheet Dashboard
A1: Saranam India Health Care — Master Manual Test Plan
A2: Manual test execution tracker • Fill Status on each module sheet • figures below update automatically
A4: # | B4: Module | C4: Sheet | D4: Total | E4: Pass | F4: Fail | G4: Blocked | H4: Not Executed | I4: % Executed | J4: % Pass
A5: 1 | B5: Patient Management | C5: Patient Management | D5: =COUNTA('Patient Management'!A2:A146) | E5: =COUNTIF('Patient Management'!L2:L146,"Pass") | F5: =COUNTIF('Patient Management'!L2:L146,"Fail") | G5: =COUNTIF('Patient Management'!L2:L146,"Blocked") | H5: =COUNTIF('Patient Management'!L2:L146,"Not Executed") | I5: =IFERROR((D5-H5)/D5,0) | J5: =IFERROR(E5/(D5-H5),0)
A6: 2 | B6: Scheduling | C6: Scheduling | D6: =COUNTA('Scheduling'!A2:A119) | E6: =COUNTIF('Scheduling'!L2:L119,"Pass") | F6: =COUNTIF('Scheduling'!L2:L119,"Fail") | G6: =COUNTIF('Scheduling'!L2:L119,"Blocked") | H6: =COUNTIF('Scheduling'!L2:L119,"Not Executed") | I6: =IFERROR((D6-H6)/D6,0) | J6: =IFERROR(E6/(D6-H6),0)
A7: 3 | B7: Providers | C7: Providers | D7: =COUNTA('Providers'!A2:A78) | E7: =COUNTIF('Providers'!L2:L78,"Pass") | F7: =COUNTIF('Providers'!L2:L78,"Fail") | G7: =COUNTIF('Providers'!L2:L78,"Blocked") | H7: =COUNTIF('Providers'!L2:L78,"Not Executed") | I7: =IFERROR((D7-H7)/D7,0) | J7: =IFERROR(E7/(D7-H7),0)
A8: 4 | B8: Inventory | C8: Inventory | D8: =COUNTA('Inventory'!A2:A121) | E8: =COUNTIF('Inventory'!L2:L121,"Pass") | F8: =COUNTIF('Inventory'!L2:L121,"Fail") | G8: =COUNTIF('Inventory'!L2:L121,"Blocked") | H8: =COUNTIF('Inventory'!L2:L121,"Not Executed") | I8: =IFERROR((D8-H8)/D8,0) | J8: =IFERROR(E8/(D8-H8),0)
A9: 5 | B9: Analytics | C9: Analytics | D9: =COUNTA('Analytics'!A2:A58) | E9: =COUNTIF('Analytics'!L2:L58,"Pass") | F9: =COUNTIF('Analytics'!L2:L58,"Fail") | G9: =COUNTIF('Analytics'!L2:L58,"Blocked") | H9: =COUNTIF('Analytics'!L2:L58,"Not Executed") | I9: =IFERROR((D9-H9)/D9,0) | J9: =IFERROR(E9/(D9-H9),0)
A10: 6 | B10: Call Logs | C10: Call Logs | D10: =COUNTA('Call Logs'!A2:A85) | E10: =COUNTIF('Call Logs'!L2:L85,"Pass") | F10: =COUNTIF('Call Logs'!L2:L85,"Fail") | G10: =COUNTIF('Call Logs'!L2:L85,"Blocked") | H10: =COUNTIF('Call Logs'!L2:L85,"Not Executed") | I10: =IFERROR((D10-H10)/D10,0) | J10: =IFERROR(E10/(D10-H10),0)
A11: 7 | B11: Users | C11: Users | D11: =COUNTA('Users'!A2:A53) | E11: =COUNTIF('Users'!L2:L53,"Pass") | F11: =COUNTIF('Users'!L2:L53,"Fail") | G11: =COUNTIF('Users'!L2:L53,"Blocked") | H11: =COUNTIF('Users'!L2:L53,"Not Executed") | I11: =IFERROR((D11-H11)/D11,0) | J11: =IFERROR(E11/(D11-H11),0)
A12: 8 | B12: Settings | C12: Settings | D12: =COUNTA('Settings'!A2:A34) | E12: =COUNTIF('Settings'!L2:L34,"Pass") | F12: =COUNTIF('Settings'!L2:L34,"Fail") | G12: =COUNTIF('Settings'!L2:L34,"Blocked") | H12: =COUNTIF('Settings'!L2:L34,"Not Executed") | I12: =IFERROR((D12-H12)/D12,0) | J12: =IFERROR(E12/(D12-H12),0)
B13: TOTAL | D13: =SUM(D5:D12) | E13: =SUM(E5:E12) | F13: =SUM(F5:F12) | G13: =SUM(G5:G12) | H13: =SUM(H5:H12) | I13: =IFERROR((D13-H13)/D13,0) | J13: =IFERROR(E13/(D13-H13),0)

Sheet Patient Management
A1: Test Case ID | B1: Section / Feature | C1: Test Title | D1: Priority | E1: Type | F1: Preconditions | G1: Test Steps | H1: Test Data | I1: Expected Result | J1: API Reference | K1: Actual Result | L1: Status | M1: Severity | N1: Tested By | O1: Date Tested | P1: Remarks / Defect ID
A2: PAT-001 | B2: Patients List - Page Load | C2: Patients list loads with default state (page 1, grid view, 20 per page) | D2: High | E2: Functional | F2: Logged in; >20 patients exist. | G2: 1. Navigate to https://saranam.fieldintel.ai/patients 2. Observe the page header, view toggle, search bar, filter chips and results | H2: N/A | I2: Page title 'Patients' with subtitle shows. Grid view is active by default. A 'Found N patients' count matches total. First 20 patient cards render. GET /api/patients?page=1&per_page=20 fires and returns 200. | J2: GET /api/patients | L2: Not Executed
A3: PAT-002 | B3: Patients List - Loading State | C3: Loading spinner shows while patients are being fetched | D3: Medium | E3: UI/UX | F3: Logged in; throttle network (DevTools Slow 3G). | G3: 1. Open /patients with network throttled 2. Observe the area while the request is in flight | H3: N/A | I3: A centered spinner with 'Fetching patient records...' is shown until data arrives, then it is replaced by cards. Results count shows 'Updating results...' during refresh. | J3: GET /api/patients | L3: Not Executed
A4: PAT-003 | B4: Patients List - Search | C4: Search by patient name returns matching patients | D4: High | E4: Functional | F4: A patient named 'Ramesh Kumar' exists. | G4: 1. Type 'Ramesh' in the search box 2. Click the Search button (or press Enter) | H4: Ramesh | I4: Page resets to 1 and GET /api/patients?q=Ramesh&page=1&per_page=20 fires. Only patients matching 'Ramesh' are listed and count updates accordingly. | J4: GET /api/patients | L4: Not Executed
A5: PAT-004 | B5: Patients List - Search | C5: Search by UHID / phone / ABHA returns the patient | D5: High | E5: Functional | F5: Patient with known UHID and phone 9876543210 exists. | G5: 1. Search by full UHID 2. Clear and search by 9876543210 3. Clear and search by ABHA id/address | H5: UHID value; 9876543210; ramesh.kumar@abdm | I5: Each search returns the correct patient (q param passed to backend). The placeholder confirms search supports name, UHID, phone, ABHA ID. | J5: GET /api/patients | L5: Not Executed
A6: PAT-005 | B6: Patients List - Search | C6: Search with no matches shows 'No Results Found' empty state | D6: Medium | E6: Edge Case | F6: Logged in. | G6: 1. Search for a string that matches no patient e.g. 'zzzqqq123' 2. Observe the empty-state panel | H6: zzzqqq123 | I6: Empty state shows 'No Results Found' heading with guidance text and a 'Clear Search Results' button. Count shows 'Found 0 patients'. | J6: GET /api/patients | L6: Not Executed
A7: PAT-006 | B7: Patients List - Search | C7: Clear Search Results restores full list | D7: Low | E7: Functional | F7: A no-match search was performed (PAT-005). | G7: 1. Click 'Clear Search Results' in the empty state | H7: N/A | I7: Search box clears, list reloads page 1 with all patients (GET /api/patients with empty q). | J7: GET /api/patients | L7: Not Executed
A8: PAT-007 | B8: Patients List - View Toggle | C8: Toggle between Grid and Table views | D8: Medium | E8: UI/UX | F8: Patients exist. | G8: 1. Click the 'Table' toggle button 2. Click the 'Grid' toggle button | H8: N/A | I8: Table view shows columns: Patient Name (with UHID), Gender, Age, Contact, Location, Status, Last Activity, Actions. Grid view shows detailed PatientCards. Toggle is client-side only (no new API call) and highlights the active button. | J8: N/A | L8: Not Executed
A9: PAT-008 | B9: Patients List - Filters | C9: BSC filter chip cycles All -> BSC Only -> N-BSC Only -> All | D9: High | E9: Functional | F9: Patients with bsc_status true and false exist. | G9: 1. Click the BSC chip once (BSC Only) 2. Click again (N-BSC Only) 3. Click again (All Patients) | H9: N/A | I9: First click sends bsc_status=true (green chip 'BSC Only'); second sends bsc_status=false (grey 'N-BSC Only'); third removes the param ('All Patients'). List + count update each time and page resets implicitly via effect. | J9: GET /api/patients?bsc_status=true|false | L9: Not Executed
A10: PAT-009 | B10: Patients List - Filters | C10: Onco filter chip cycles All Types -> Onco Only -> Non-Onco Only -> All | D10: High | E10: Functional | F10: Patients with is_onco true and false exist. | G10: 1. Click the Onco chip three times observing each state | H10: N/A | I10: Sends is_onco=true, then is_onco=false, then no param. Chip label and color change (orange/purple/neutral) and results filter accordingly. | J10: GET /api/patients?is_onco=true|false | L10: Not Executed
A11: PAT-010 | B11: Patients List - Filters | C11: Zone filter chips filter by geographic_cluster and toggle off | D11: High | E11: Functional | F11: Patients exist in North and South zones. | G11: 1. Click the 'South' zone chip 2. Click 'South' again to clear 3. Click 'North' | H11: South / North | I11: Clicking 'South' sends geographic_cluster=South and highlights it blue; only South patients show. Clicking again clears it. Selecting a different zone replaces the filter. | J11: GET /api/patients?geographic_cluster=South | L11: Not Executed
A12: PAT-011 | B12: Patients List - Filters | C12: Combine BSC + Onco + Zone filters together | D12: Medium | E12: Functional | F12: A BSC + Onco + South patient exists. | G12: 1. Set BSC Only, Onco Only, and Zone South 2. Observe results and the request | H12: N/A | I12: GET /api/patients includes bsc_status=true, is_onco=true and geographic_cluster=South together; only patients matching all three are returned. | J12: GET /api/patients?bsc_status=true&is_onco=true&geographic_cluster=South | L12: Not Executed
A13: PAT-012 | B13: Patients List - Filters | C13: 'Clear filters' link appears and resets all chips | D13: Medium | E13: Functional | F13: At least one filter is active. | G13: 1. Activate any combination of BSC/Onco/Zone filters 2. Click 'Clear filters' | H13: N/A | I13: The 'Clear filters' control only renders when a filter is active. Clicking it resets BSC, Onco and Zone to default and reloads the unfiltered list. | J13: GET /api/patients | L13: Not Executed
... A146: PAT-145 | B146: Registration - Vitals/Numeric Boundary (PPS Card) | C146: Cannot save a PPS without selecting a row in the universal card | D146: Low | E146: Validation | F146: Patient with no priority/PPS; PPS card dialog open. | G146: 1. Open Record PPS where no default applies, do not click a row, click Save PPS | H146: N/A | I146: Save is disabled / alerts 'Please select a PPS score'; no POST is sent. | J146: POST /api/patients/:id/pps | L146: Not Executed

Sheet Scheduling
A1: Test Case ID | B1: Section / Feature | C1: Test Title | D1: Priority | E1: Type | F1: Preconditions | G1: Test Steps | H1: Test Data | I1: Expected Result | J1: API Reference | K1: Actual Result | L1: Status | M1: Severity | N1: Tested By | O1: Date Tested | P1: Remarks / Defect ID
A2: SCH-001 | B2: Schedule Calendar | C2: Calendar page loads with header, tabs and schedule list | D2: High | E2: Functional | F2: Logged in; at least one schedule and one vehicle exist. | G2: 1. Navigate to /saranam/scheduling 2. Wait for the spinner to finish | H2: N/A | I2: Header 'Schedule Calendar / Weekly schedule overview' shows with Calendar icon. Refresh, Quick Create and New Schedule buttons render. Five status tabs (All, Draft, Submitted, Active, Archived) each show a count badge. The schedule table lists Week, Status, Patients, Days, Actions columns sorted newest week first. | J2: GET /api/saranam/scheduling/schedules?per_page=100 and GET /api/saranam/scheduling/vehicles | L2: Not Executed
A3: SCH-002 | B3: Schedule Calendar | C3: Status tab filtering segregates schedules correctly | D3: High | E3: Functional | F3: Schedules exist in draft, submitted, approved/in_progress and archived statuses. | G3: 1. On the calendar, click each tab: All, Draft, Submitted, Active, Archived | H3: N/A | I3: Draft tab shows only status=draft; Submitted only submitted; Active shows approved/communicated/in_progress/review_ready; Archived only archived; All shows everything. Counts in tab badges match the rows shown. | J3: N/A (client-side filter of GET /schedules result) | L3: Not Executed
A4: SCH-003 | B4: Schedule Calendar | C4: Deep link ?status=pending opens the Submitted tab (Drafts & Approvals) | D4: High | E4: Functional | F4: Logged in. | G4: 1. Navigate directly to /saranam/scheduling?status=pending | H4: URL query status=pending | I4: Page opens with the Submitted tab pre-selected (activeTab index 1), listing only submitted schedules awaiting approval. | J4: GET /api/saranam/scheduling/schedules?per_page=100 | L4: Not Executed
A5: SCH-004 | B5: Schedule Calendar | C5: Refresh button reloads schedules and vehicles | D5: Medium | E5: Functional | F5: Calendar loaded. | G5: 1. Create/modify a schedule in another tab 2. Click Refresh on the calendar | H5: N/A | I5: List re-fetches and reflects the latest data; spinner shows briefly during load. | J5: GET /api/saranam/scheduling/schedules + GET /api/saranam/scheduling/vehicles | L5: Not Executed
A6: SCH-005 | B6: Schedule Calendar | C6: New Schedule dialog creates a schedule and opens the board | D6: High | E6: Functional | F6: At least one vehicle configured. | G6: 1. Click New Schedule 2. In the dialog pick Week Start Date 2026-06-08 3. Click Create | H6: Week Start = 2026-06-08 | I6: Schedule is created (uses vehicles[0]) and the app navigates to /saranam/scheduling/board/<newId>. Dialog closes and Create shows 'Creating...' while saving. | J6: POST /api/saranam/scheduling/schedules {week_start_date, vehicle_id} | L6: Not Executed
A7: SCH-006 | B7: Schedule Calendar | C7: Create is disabled until a week start date is chosen | D7: Medium | E7: Validation | F7: New Schedule dialog open. | G7: 1. Open New Schedule dialog 2. Leave Week Start Date empty 3. Observe the Create button | H7: Empty date | I7: Create button is disabled while the date field is empty; enabling only after a date is selected. | J7: N/A | L7: Not Executed
A8: SCH-007 | B8: Schedule Calendar | C8: Quick Create makes a schedule for the current week's Monday | D8: Medium | E8: Functional | F8: At least one vehicle configured. | G8: 1. Click Quick Create | H8: N/A (today 2026-06-01 -> Monday 2026-06-01) | I8: A schedule for the current week's Monday is created with vehicles[0] and the board opens. Button shows disabled state while creating. | J8: POST /api/saranam/scheduling/schedules | L8: Not Executed
A9: SCH-008 | B9: Schedule Calendar | C9: Create blocked when no vehicles configured | D9: High | E9: Negative | F9: No vehicles exist (delete/avoid configuring any). | G9: 1. Click Quick Create (or New Schedule -> pick date -> Create) | H9: N/A | I9: An error banner shows 'No vehicles configured. Add a vehicle in Settings first.' and no schedule is created/navigation occurs. | J9: N/A (guarded client-side before POST) | L9: Not Executed
A10: SCH-009 | B10: Schedule Calendar | C10: Open / View action navigates by status | D10: Medium | E10: Functional | F10: Schedules in various statuses exist. | G10: 1. Click a non-review_ready row (or its Open button) 2. Go back, click a review_ready row 3. Go back, observe an archived row's button label | H10: N/A | I10: Non review_ready rows open /board/:id. review_ready rows open /review-dashboard/:id. Archived rows show 'View' label (others show 'Open'). | J10: N/A (navigation) | L10: Not Executed
A11: SCH-010 | B11: Schedule Calendar | C11: Schedule PDF download (Schedule button) | D11: Medium | E11: Functional | F11: A schedule with patient slots exists. | G11: 1. On a row click the 'Schedule' (Download) button | H11: N/A | I11: Export data is fetched and a schedule PDF is generated/downloaded. On a PDF generation error an error banner 'PDF generation failed: ...' is shown. | J11: GET /api/saranam/scheduling/schedules/{id}/export-data | L11: Not Executed
A12: SCH-011 | B12: Schedule Calendar | C12: Weekly Report button only on active/completed schedules | D12: Medium | E12: Functional | F12: An active/in_progress/review_ready/completed schedule with deviations exists; also a draft schedule exists. | G12: 1. Locate an active schedule row -> click 'Report' 2. Locate a draft schedule row and confirm no Report button | H12: N/A | I12: Report button appears only for active/in_progress/review_ready/completed rows; clicking fetches schedule detail + deviations and generates the weekly report PDF. Draft/submitted rows have no Report button. On failure an alert 'Failed to generate report' shows. | J12: GET /schedules/{id} + GET /schedules/{id}/deviations | L12: Not Executed
A13: SCH-012 | B13: Schedule Calendar | C13: Delete schedule with confirmation removes it | D13: High | E13: Functional | F13: A deletable schedule exists. | G13: 1. Click the red trash icon on a row 2. Confirm the browser confirm dialog warning about removing assignments, team and audit logs | H13: N/A | I13: On confirm the schedule is deleted and the list reloads without it. Cancelling the confirm leaves it intact. On backend error an error banner appears. | J13: DELETE /api/saranam/scheduling/schedules/{id} | L13: Not Executed
... A119: SCH-118 | B119: Regression / Stability | C119: Browser back/forward between scheduling screens preserves data | D119: Low | E119: UI/UX | F119: Logged in. | G119: 1. Calendar -> open a board -> browser Back -> Active Visits -> Back | H119: N/A | I119: Each screen reloads its own data cleanly on navigation; no stale data leaks between schedules; tab selection on the calendar is preserved per the URL/state. | J119: N/A | L119: Not Executed

Sheet Providers
A1: Test Case ID | B1: Section / Feature | C1: Test Title | D1: Priority | E1: Type | F1: Preconditions | G1: Test Steps | H1: Test Data | I1: Expected Result | J1: API Reference | K1: Actual Result | L1: Status | M1: Severity | N1: Tested By | O1: Date Tested | P1: Remarks / Defect ID
A2: PRV-001 | B2: Providers List | C2: Providers list loads with default Active filter on first visit | D2: High | E2: Functional | F2: Logged in. At least 5 active providers exist. | G2: 1. Navigate to /providers. 2. Observe the page header 'Healthcare Providers' and subtitle. 3. Wait for the providers to load. | H2: N/A | I2: Page header and 'Add Provider' button render. A brief loading spinner ('Loading providers...') may appear, then a responsive card grid of ACTIVE providers (status filter defaults to 'Active'). The count line 'Showing N provider(s)' matches the number of cards. Each card shows full_name, specialization, an Active badge, and any of license/email/phone present. | J2: GET /api/providers (is_active=true, limit=100); GET /api/providers/specializations | L2: Not Executed
A3: PRV-002 | B3: Providers List | C3: Specialization filter dropdown is populated from API | D3: Medium | E3: Functional | F3: Logged in. Specializations exist in system. | G3: 1. Open /providers. 2. Open the Specialization dropdown. | H3: N/A | I3: Dropdown lists 'All Specializations' first, followed by each specialization returned by GET /providers/specializations. No duplicates or blank entries. | J3: GET /api/providers/specializations | L3: Not Executed
A4: PRV-003 | B4: Providers List | C4: Search filters providers by name/license/HPR ID | D4: High | E4: Functional | F4: Logged in. A provider named like 'Dr. Anjali Rao' exists. | G4: 1. Open /providers. 2. Type 'Anjali' into the Search field. 3. Observe the list updating as you type. | H4: Search: Anjali | I4: List re-queries on each keystroke (useEffect on searchQuery) and shows only matching providers. Count line updates accordingly. A network call to GET /providers with search=Anjali is sent. | J4: GET /api/providers (search=Anjali) | L4: Not Executed
A5: PRV-004 | B5: Providers List | C5: Search with no matches shows search-specific empty state | D5: Medium | E5: UI/UX | F5: Logged in. | G5: 1. Open /providers. 2. Type a string that matches no provider, e.g. 'zzzzzzzz'. 3. Observe the result area. | H5: Search: zzzzzzzz | I5: Empty-state card appears with stethoscope icon, heading 'No providers found' and the search-specific message 'No providers match your search criteria.' plus an 'Add Provider' button. | J5: GET /api/providers (search=zzzzzzzz) | L5: Not Executed
A6: PRV-005 | B6: Providers List | C6: Filter by a specific specialization | D6: High | E6: Functional | F6: Logged in. Providers with at least two distinct specializations exist. | G6: 1. Open /providers. 2. Select a specific specialization (e.g., 'Oncology') from the Specialization dropdown. | H6: Specialization: Oncology | I6: List refreshes to show only providers whose specialization matches the selection. Count updates. GET /providers is called with specialization=Oncology. | J6: GET /api/providers (specialization=Oncology) | L6: Not Executed
A7: PRV-006 | B7: Providers List | C7: Status filter Inactive shows only inactive providers | D7: High | E7: Functional | F7: Logged in. At least one inactive provider exists. | G7: 1. Open /providers. 2. Open the Status dropdown and choose 'Inactive'. | H7: Status: Inactive | I7: List re-queries with is_active=false and shows only providers with a grey 'Inactive' badge. GET /providers is sent with is_active=false. | J7: GET /api/providers (is_active=false) | L7: Not Executed
A8: PRV-007 | B8: Providers List | C8: Status filter 'All' behaviour (is_active omitted, backend defaults to active) | D8: Medium | E8: Edge Case | F8: Logged in. Mix of active and inactive providers exist. | G8: 1. Open /providers. 2. Set Status = 'All'. 3. Inspect the GET /providers request in browser DevTools Network tab. 4. Observe which providers are returned. | H8: Status: All | I8: Frontend omits is_active when 'All' is selected. NOTE/KNOWN BEHAVIOUR: backend defaults is_active to true when the param is absent, so 'All' effectively returns only ACTIVE providers (inactive ones do NOT appear). Verify whether returned set matches 'Active' or truly all; log any discrepancy as a defect for the dev team. | J8: GET /api/providers (is_active omitted) | L8: Not Executed
A9: PRV-008 | B9: Providers List | C9: Refresh button reloads the list and shows spinner state | D9: Medium | E9: Functional | F9: Logged in. | G9: 1. Open /providers. 2. Click the circular Refresh (RefreshCw) button next to the Status filter. 3. Observe the icon and list. | H9: N/A | I9: Refresh icon spins (animate-spin) and the button is disabled while loading; a fresh GET /providers is issued with the current filters; list re-renders. Button re-enables when done. | J9: GET /api/providers | L9: Not Executed
A10: PRV-009 | B10: Providers List | C10: Clicking a provider card navigates to detail | D10: High | E10: Functional | F10: Logged in. At least one provider exists. | G10: 1. Open /providers. 2. Click anywhere on a provider card (not the View Details button). | H10: N/A | I10: Browser navigates to /providers/{id} for that provider and the detail page loads. URL contains the provider's UUID. | J10: GET /api/providers/{provider_id}; GET /api/providers/{provider_id}/schedule | L10: Not Executed
A11: PRV-010 | B11: Providers List | C11: View Details button navigates without double-trigger | D11: Low | E11: UI/UX | F11: Logged in. At least one provider exists. | G11: 1. Open /providers. 2. Click the 'View Details' button inside a provider card. | H11: N/A | I11: Navigates to /providers/{id}. The button's stopPropagation prevents the card onClick from firing twice; navigation happens exactly once to the correct provider. | J11: GET /api/providers/{provider_id} | L11: Not Executed
A12: PRV-011 | B12: Providers List | C12: Add Provider button (header) opens create form | D12: High | E12: Functional | F12: Logged in. | G12: 1. Open /providers. 2. Click the top-right 'Add Provider' button. | H12: N/A | I12: Navigates to /providers/new showing 'Add New Provider' form with empty fields and consultation_duration defaulted to 30. | J12: N/A (navigation); GET /api/providers/specializations on form load | L12: Not Executed
A13: PRV-012 | B13: Providers List | C13: Empty state when no providers exist at all | D13: Medium | E13: UI/UX | F13: Logged in. A filter combination that yields zero providers (e.g., a specialization with no providers and no search text). | G13: 1. Open /providers. 2. Apply a specialization filter that has no providers. | H13: Specialization with zero providers | I13: Empty-state card shows 'No providers found' with the non-search message 'Get started by adding your first healthcare provider.' and an 'Add Provider' CTA. | J13: GET /api/providers | L13: Not Executed
... A78: PRV-077 | B78: Edit Provider | C78: Edit form load failure shows error alert | D78: Medium | E78: Negative | F78: Logged in. Ability to force GET /providers/{id} to fail when opening edit. | G78: 1. Force GET /providers/{id} to 500. 2. Open /providers/{id}/edit. | H78: Forced 500 | I78: Destructive Alert 'Failed to load form data. Please try again.' is shown; the form is not usefully prefilled. (Specializations may still load independently.) | J78: GET /api/providers/{provider_id} (forced error) | L78: Not Executed

Sheet Inventory
A1: Test Case ID | B1: Section / Feature | C1: Test Title | D1: Priority | E1: Type | F1: Preconditions | G1: Test Steps | H1: Test Data | I1: Expected Result | J1: API Reference | K1: Actual Result | L1: Status | M1: Severity | N1: Tested By | O1: Date Tested | P1: Remarks / Defect ID
A2: INV-001 | B2: Dashboard | C2: Inventory Dashboard loads with all six KPI stat cards | D2: High | E2: Functional | F2: Logged in as admin; seed data present. | G2: 1. Navigate to /inventory. 2. Observe the spinner 'Loading inventory...' then the loaded dashboard. 3. Verify the six stat cards render: Total Medicines, Stock Locations, Total Stock Value, Low Stock Items, Expiring Soon, Active Suppliers. | H2: N/A | I2: All six cards render with numeric values. Total Stock Value is formatted with ₹ and Indian grouping. Values are derived from getMedicines, getLocations, getStock, getSuppliers, getBatches calls. | J2: GET /api/inventory/medicines, GET /api/inventory/locations, GET /api/inventory/stock, GET /api/inventory/suppliers, GET /api/inventory/batches | L2: Not Executed
A3: INV-002 | B3: Dashboard | C3: Dashboard low-stock and expiring-soon alert styling | D3: Medium | E3: UI/UX | F3: Seed data has at least one LOW/CRITICAL stock item and at least one batch expiring within 90 days. | G3: 1. Open /inventory. 2. Inspect the 'Low Stock Items' and 'Expiring Soon' cards. | H3: N/A | I3: When value > 0 the card shows a red ring (ring-2 ring-red-200) and a pulsing red dot. Low Stock counts items with stock_status StockStatus.LOW or StockStatus.CRITICAL; Expiring Soon counts batches with days_to_expiry between 1 and 89. | J3: GET /api/inventory/stock, GET /api/inventory/batches | L3: Not Executed
A4: INV-003 | B4: Dashboard | C4: Dashboard stat-card links navigate to correct screens | D4: Medium | E4: Functional | F4: Logged in as admin. | G4: 1. On /inventory click 'Total Medicines' card -> expect /inventory/medicines. 2. Back. Click 'Stock Locations', 'Total Stock Value', 'Low Stock Items', 'Expiring Soon' -> each routes to /inventory/stock. 3. Back. Click 'Active Suppliers' -> expect /inventory/purchase-orders. | H4: N/A | I4: Each card navigates to its configured href without error. | J4: N/A | L4: Not Executed
A5: INV-004 | B5: Dashboard | C5: Quick Actions and Module cards navigation | D5: Medium | E5: Functional | F5: Logged in as admin. | G5: 1. Click Quick Action 'New Medicine' -> /inventory/medicines. 2. Click 'Purchase Order' -> /inventory/purchase-orders/new. 3. Click 'Dispense' -> /inventory/dispense. 4. Click 'Stock Report' -> /inventory/stock. 5. Click each of the 4 Module cards and confirm correct route. | H5: N/A | I5: All Quick Action and Module links route correctly. | J5: N/A | L5: Not Executed
A6: INV-005 | B6: Dashboard | C6: Dashboard Refresh button re-fetches stats | D6: Low | E6: Functional | F6: Logged in as admin; DevTools Network open. | G6: 1. Open /inventory. 2. Click the Refresh (circular arrow) button top-right. 3. Watch the Network tab. | H6: N/A | I6: The five parallel GET calls fire again and the cards re-render with current data; brief loading spinner is acceptable. | J6: GET /api/inventory/medicines, GET /api/inventory/locations, GET /api/inventory/stock, GET /api/inventory/suppliers, GET /api/inventory/batches | L6: Not Executed
A7: INV-006 | B7: Dashboard | C7: Dashboard resilient when an underlying API errors | D7: Medium | E7: Edge Case | F7: Ability to force a 500 on one of the dashboard calls (e.g. block /inventory/batches in DevTools). | G7: 1. Block or fail one of the five dashboard requests. 2. Reload /inventory. | H7: N/A | I7: Because all five are awaited in a single Promise.all, a single failure causes the catch branch: stats stay at defaults (zeros) and an error is logged to console; the page still renders without crashing (no white screen). | J7: GET /api/inventory/batches | L7: Not Executed
A8: INV-007 | B8: Medicines Master | C8: Medicines list loads with header count and table columns | D8: High | E8: Functional | F8: Logged in as admin; medicines seeded. | G8: 1. Navigate to /inventory/medicines. 2. Verify header shows 'Medicine Master' and a subtitle '<total> medicines'. 3. Verify columns: Code, Medicine Name, Generic, Brand, Strength, Form, Category, Status, Actions. | H8: N/A | I8: Table lists medicines (25 per page). Form badge strips the 'DosageForm.' prefix. Status shows 'Essential' or 'Non-Essential'. Subtitle equals API total. | J8: GET /api/inventory/medicines?page=1&per_page=25 | L8: Not Executed
A9: INV-008 | B9: Medicines Master | C9: Medicine search filters list and resets to page 1 | D9: High | E9: Functional | F9: At least 2 distinct medicines seeded. | G9: 1. On /inventory/medicines navigate to page 2 (if available). 2. Type 'Paracetamol' into the search box. 3. Observe the table and watch Network. | H9: Search: Paracetamol | I9: On each keystroke the list re-fetches with search=Paracetamol and page resets to 1; only matching medicines show. | J9: GET /api/inventory/medicines?page=1&per_page=25&search=Paracetamol | L9: Not Executed
A10: INV-009 | B10: Medicines Master | C10: Medicines empty state when no match found | D10: Low | E10: UI/UX | F10: Logged in as admin. | G10: 1. Search for a string that matches nothing, e.g. 'zzzznomatch'. 2. Wait for the result. | H10: Search: zzzznomatch | I10: Table body shows the centered Pill icon with 'No medicines found'. Pagination is hidden. | J10: GET /api/inventory/medicines?search=zzzznomatch | L10: Not Executed
A11: INV-010 | B11: Medicines Master | C11: Medicines pagination Prev/Next behaviour | D11: Medium | E11: Functional | F11: More than 25 medicines exist (total > 25). | G11: 1. Open /inventory/medicines. 2. Confirm 'Page 1 of N (total)' footer is shown and Prev is disabled. 3. Click Next; confirm page increments and data changes. 4. On the last page confirm Next is disabled. | H11: N/A | I11: Prev disabled on page 1; Next disabled on last page; page label and totals are accurate; totalPages = ceil(total/25). | J11: GET /api/inventory/medicines?page=2&per_page=25 | L11: Not Executed
A12: INV-011 | B12: Medicines Master | C12: Add Medicine dialog opens with default form values | D12: Medium | E12: UI/UX | F12: Logged in as admin. | G12: 1. Click 'Add Medicine'. 2. Inspect the dialog field defaults. | H12: N/A | I12: Dialog titled 'Add New Medicine' opens; defaults: dosage_form Tablet, unit Tablets, pack_size 10, drug schedule H, NLEM P, storage Room Temperature (15-25°C), GST 12, Generic and Essential checked. Required markers (*) on Medicine Name and Generic Name. | J12: N/A | L12: Not Executed
A13: INV-012 | B13: Medicines Master | C13: Create medicine with all valid fields | D13: High | E13: Functional | F13: Logged in as admin (write permission). | G13: 1. Open Add Medicine dialog. 2. Fill: Medicine Name 'Amoxicillin', Generic 'Amoxicillin', Brand 'Mox', Manufacturer 'Cipla', Dosage Form Capsule, Strength '500mg', Unit 'Capsules', Pack Size 10, Category 'Antibiotics', Schedule H, HSN '30049099', GST 12, Storage Room Temperature. 3. Click Create. | H13: Amoxicillin 500mg Capsule, GST 12%, HSN 30049099 | I13: POST returns 201; dialog closes; green success banner 'Medicine created' (auto-hides after 3s); list refreshes and shows the new medicine with an auto-generated code. | J13: POST /api/inventory/medicines | L13: Not Executed
... A121: INV-120 | B121: API | C121: Patient prescriptions endpoint requires UUID patient id | D121: Low | E121: API | F121: Valid token. | G121: 1. Call GET /inventory/prescriptions/patient/not-a-uuid. 2. Call GET /inventory/prescriptions/patient/{valid-uuid}. | H121: patient_id = 'abc' then a valid UUID | I121: Non-UUID path does not match the <uuid:patient_id> converter and returns 404 (route not matched); a valid UUID returns {prescriptions, total} aggregating OPD + Saranam plan-of-care, or an empty list if none. | J121: GET /api/inventory/prescriptions/patient/{patient_id} | L121: Not Executed

Sheet Analytics
A1: Test Case ID | B1: Section / Feature | C1: Test Title | D1: Priority | E1: Type | F1: Preconditions | G1: Test Steps | H1: Test Data | I1: Expected Result | J1: API Reference | K1: Actual Result | L1: Status | M1: Severity | N1: Tested By | O1: Date Tested | P1: Remarks / Defect ID
A2: ANL-001 | B2: Permission & Access | C2: User WITH view_analytics permission can open /analytics | D2: High | E2: Permission | F2: Logged in as Account A (has view_analytics). | G2: 1. Log in as Account A. 2. Navigate to /analytics (via the Analytics nav item or direct URL). 3. Observe the page. | H2: analyst@saranam.test | I2: The Analytics Dashboard renders: 'Analytics Dashboard' title, the tab toggle group (Patient, Forms, Vitals, Donor / ToC), date controls and the Patient view content. No Access Denied panel. | J2: GET /api/analytics/dashboard | L2: Not Executed
A3: ANL-002 | B3: Permission & Access | C3: User WITHOUT view_analytics permission is blocked | D3: High | E3: Permission | F3: Logged in as Account B (no view_analytics). | G3: 1. Log in as Account B. 2. Attempt to open /analytics via direct URL. 3. Observe the page. | H3: fieldnurse@saranam.test | I3: ProtectedRoute renders the 'Access Denied — You don't have permission to access this page.' panel. The dashboard content and any analytics API call are NOT made. | J3: N/A | L3: Not Executed
A4: ANL-003 | B4: Permission & Access | C4: Unauthenticated access to /analytics redirects to login | D4: High | E4: Permission | F4: No active session (localStorage cleared / logged out). | G4: 1. Clear localStorage (access_token, refresh_token, user) or log out. 2. Open /analytics directly. 3. Observe navigation. | H4: N/A | I4: ProtectedRoute finds no user and redirects to /login (Navigate replace). The Analytics Dashboard is not shown. | J4: N/A | L4: Not Executed
A5: ANL-004 | B5: Permission & Access | C5: Analytics API requires a valid Bearer token (401 when missing) | D5: High | E5: API | F5: Account A logged in; DevTools available. | G5: 1. Open /analytics. 2. In DevTools, manually delete/blank the access_token in localStorage, then trigger a refresh of the Patient view (Refresh button or change date range). 3. Inspect the /api/analytics/dashboard request and response. | H5: N/A | I5: Request goes out with an invalid/empty Authorization header; backend (@require_auth) returns 401. The dashboard shows the red 'Error loading dashboard' panel with a 'Try Again' button (no app crash). NOTE: because the dashboard uses raw axios, the apiClient 401 refresh-and-retry does NOT run. | J5: GET /api/analytics/dashboard | L5: Not Executed
A6: ANL-005 | B6: Dashboard Shell | C6: Default view on load is Patient with Last-12-months range | D6: High | E6: Functional | F6: Account A logged in. | G6: 1. Open /analytics fresh. 2. Observe which tab is active and the date range shown in the picker. | H6: N/A | I6: The 'Patient' tab is active (highlighted) by default. The DateRangePicker shows a range from ~12 months ago to today (e.g. Jun 1, 2025 - Jun 1, 2026). The patient-type filter (All Patients) is visible only on this view. | J6: GET /api/analytics/dashboard, GET /api/analytics/deaths/impact | L6: Not Executed
A7: ANL-006 | B7: Dashboard Shell | C7: Tab navigation switches between all four live views | D7: High | E7: Functional | F7: Account A on /analytics. | G7: 1. Click the 'Forms' tab; observe content and subtitle. 2. Click the 'Vitals' tab; observe content. 3. Click the 'Donor / ToC' tab; observe content. 4. Click back to 'Patient'. | H7: N/A | I7: Each click activates the corresponding tab (highlighted) and renders that view's content. The header subtitle updates per view (e.g. 'form usage and completion', 'vital sign trends and clinical correlations', 'Theory of Change-aligned stewardship', 'patient demographics and operational'). Only one view is visible at a time. | J7: GET /api/analytics/dashboard, GET /api/analytics/forms, GET /api/analytics/vitals/summary, GET /api/analytics/donor/overview | L7: Not Executed
A8: ANL-007 | B8: Dashboard Shell | C8: Only Patient / Forms / Vitals / Donor tabs are present (hidden views absent) | D8: Medium | E8: UI/UX | F8: Account A on /analytics. | G8: 1. Inspect the tab toggle group. 2. Confirm which tab buttons are rendered. | H8: N/A | I8: Exactly four tab buttons render: Patient, Forms, Vitals, Donor / ToC. The Symptoms, Risk, Geospatial, Optimization, Outcomes and Financial tabs are NOT present (commented out in code) and there is no way to reach those views from the UI. | J8: N/A | L8: Not Executed
A9: ANL-008 | B9: Dashboard Shell | C9: Loading skeletons appear while patient data is fetched | D9: Medium | E9: UI/UX | F9: Account A; DevTools Network throttling set to Slow 3G. | G9: 1. Throttle the network in DevTools. 2. Open /analytics (Patient view). 3. Observe the StatCards and ChartCards during the fetch. | H9: N/A | I9: While loading, StatCards and ChartCards show skeleton placeholders (grey shimmer blocks) instead of values/charts; once /analytics/dashboard resolves, real values and charts replace them. The Refresh icon spins while loading. | J9: GET /api/analytics/dashboard | L9: Not Executed
A10: ANL-009 | B10: Dashboard Shell | C10: Dashboard error panel renders when /analytics/dashboard fails (500) | D10: High | E10: Negative | F10: Account A; ability to force the dashboard call to fail (DevTools request block or backend 500). | G10: 1. Open /analytics. 2. Block or force a 500 on GET /api/analytics/dashboard, then click Refresh. 3. Observe the page. | H10: N/A | I10: The page shows the red 'Error loading dashboard' box with the server error message and a 'Try Again' button. No blank screen or JS crash. Clicking 'Try Again' re-issues the fetch. | J10: GET /api/analytics/dashboard | L10: Not Executed
A11: ANL-010 | B11: Dashboard Shell | C11: Refresh button re-fetches the active view | D11: Medium | E11: Functional | F11: Account A on /analytics (Patient view); DevTools Network open. | G11: 1. Note the current /api/analytics/dashboard request in Network. 2. Click the circular Refresh (RefreshCw) button. 3. Observe Network and the spinner. | H11: N/A | I11: A fresh GET /api/analytics/dashboard fires with the same current params; the Refresh icon spins (animate-spin) and is disabled while loading; data re-renders on completion. On the Forms tab the same button refetches /api/analytics/forms. | J11: GET /api/analytics/dashboard | L11: Not Executed
A12: ANL-011 | B12: Patient Analysis View | C12: Summary StatCards render correct headline figures | D12: High | E12: Functional | F12: Account A on Patient view with data present. | G12: 1. Open /analytics (Patient). 2. Read the three top StatCards: Total Patients, New Patients, Total Forms. 3. Compare values to the /api/analytics/dashboard summary in Network. | H12: N/A | I12: Total Patients = summary.total_patients, New Patients = summary.new_patients (with a growth_rate trend badge vs last month), Total Forms = summary.total_forms, all locale-formatted (e.g. 1,234). Values match the API JSON exactly. | J12: GET /api/analytics/dashboard | L12: Not Executed
A13: ANL-012 | B13: Patient Analysis View | C13: Palliative Outcomes cards reflect deaths/impact (window_days=30) | D13: High | E13: Functional | F13: Account A; at least one death recorded in last 30 days. | G13: 1. Open /analytics (Patient). 2. Read the 'Deaths (Last 30 Days)' and 'Avg Visits Before Death' cards. 3. Inspect the GET /api/analytics/deaths/impact?window_days=30 response. | H13: window_days=30 | I13: Deaths (Last 30 Days) = deaths_in_window; Avg Visits Before Death = avg_visits_before_death formatted to 1 decimal. These cards fetch independently and keep their own loading skeleton; a deaths/impact failure does NOT blank the other StatCards. | J13: GET /api/analytics/deaths/impact | L13: Not Executed
... A58: ANL-057 | B58: Advanced Form Analytics (Out of Scope - Guard Only) | C58: /analytics/forms and /analytics/forms/:formId blocked without permission | D58: Low | E58: Permission | F58: Account B (no view_analytics). | G58: 1. As Account B, open /analytics/forms and then /analytics/forms/<any-form-id> directly. 2. Observe. | H58: any formId | I58: Both routes show the ProtectedRoute 'Access Denied' panel (same guard as /analytics). Deep deep-dive testing remains OUT OF SCOPE. | J58: N/A | L58: Not Executed

Sheet Call Logs
A1: Test Case ID | B1: Section / Feature | C1: Test Title | D1: Priority | E1: Type | F1: Preconditions | G1: Test Steps | H1: Test Data | I1: Expected Result | J1: API Reference | K1: Actual Result | L1: Status | M1: Severity | N1: Tested By | O1: Date Tested | P1: Remarks / Defect ID
A2: CL-001 | B2: Permission & Access | C2: Admin can open /call-logs and lands on the Dial tab | D2: High | E2: Permission | F2: Logged in as admin user; at least 1 patient and 1 provider exist. | G2: 1. Log in as the admin user. 2. Navigate to https://saranam.fieldintel.ai/call-logs (or click the 'Call Logs' sidebar item). 3. Observe the page header and the active tab. | H2: admin@saranam.test | I2: Page renders with title 'Smart Outreach' and subtitle 'Integrated patient communication hub and automated call history.'. The 'Dial' tab is active by default; Dial/History/Escalated/Scheduler toggle buttons are visible; the Staff Registry sidebar is shown. | J2: GET /api/exotel/agents | L2: Not Executed
A3: CL-002 | B3: Permission & Access | C3: Non-admin user is blocked from /call-logs (Access Denied) | D3: High | E3: Permission | F3: Logged in as a non-admin user (role data_entry or viewer). | G3: 1. Log in as a non-admin user. 2. Manually navigate to /call-logs via the URL bar. 3. Observe the rendered content. | H3: viewer@saranam.test (role=viewer) | I3: ProtectedRoute renders a full-page 'Access Denied' message ('You don't have permission to access this page.'); CallLogsPage and its API calls do NOT execute. | J3: N/A | L3: Not Executed
A4: CL-003 | B4: Permission & Access | C4: 'Call Logs' sidebar item visibility for a non-admin (KNOWN DEFECT) | D4: High | E4: Permission | F4: Logged in as a non-admin user; DashboardLayout sidebar visible. | G4: 1. Log in as a non-admin user (viewer/data_entry). 2. Open the left navigation sidebar. 3. Look for the 'Call Logs' menu item. 4. Click it if present. | H4: viewer@saranam.test | I4: EXPECTED PER REQUIREMENT: the 'Call Logs' item should be hidden for non-admins. ACTUAL (defect): the nav entry has permission:null and is filtered by `!item.permission || hasPermission(...)`, so it is ALWAYS shown; the non-admin sees 'Call Logs' and on click reaches the 'Access Denied' page. Log as FAIL and reference DEF-CL-01. | J4: N/A | L4: Not Executed
A5: CL-004 | B5: Permission & Access | C5: Unauthenticated user is redirected to /login | D5: High | E5: Permission | F5: No active session (localStorage cleared of access_token/user). | G5: 1. Clear site data / log out so there is no user in context. 2. Navigate directly to /call-logs. | H5: N/A | I5: ProtectedRoute sees no user and redirects (Navigate replace) to /login. CallLogsPage does not render. | J5: N/A | L5: Not Executed
A6: CL-005 | B6: Permission & Access | C6: Expired access token on a guarded call triggers refresh then retry | D6: Medium | E6: API | F6: Logged in as admin; access_token expired but a valid refresh_token present. | G6: 1. Set access_token in localStorage to an expired/invalid token, keep a valid refresh_token. 2. Open /call-logs (triggers GET /api/exotel/agents). 3. Watch the Network tab. | H6: N/A | I6: First agents call returns 401; client posts /auth/refresh with the refresh token, stores the new access_token, and retries the original request which now succeeds (200). Staff Registry populates without forcing logout. | J6: GET /api/exotel/agents | L6: Not Executed
A7: CL-006 | B7: Permission & Access | C7: Failed token refresh on 401 logs the user out to /login | D7: Medium | E7: API | F7: Logged in as admin; both access_token and refresh_token invalid/expired. | G7: 1. Invalidate both access_token and refresh_token in localStorage. 2. Open /call-logs. 3. Observe redirect behaviour. | H7: N/A | I7: Guarded call returns 401, refresh attempt fails, client clears access_token/refresh_token/user from localStorage and redirects to /login. | J7: GET /api/exotel/agents | L7: Not Executed
A8: CL-007 | B8: Dial - Outreach Queue | C8: Dial tab loads the priority outreach queue with patients and pagination footer | D8: High | E8: Functional | F8: Admin on /call-logs, >10 patients seeded. | G8: 1. Open the Dial tab. 2. Observe the 'Patients' card titled 'Priority Outreach Queue'. 3. Read the footer 'Showing X to Y of Z' text. | H8: 12 seeded patients | I8: GET /api/patients (page=1, per_page=10, search='') is called; up to 10 patient rows render with name, patient phone, last sync date and a status badge; footer reads 'Showing 1 to 10 of 12'; Next enabled, Previous disabled on page 1. | J8: GET /api/patients?page=1&per_page=10 | L8: Not Executed
A9: CL-008 | B9: Dial - Outreach Queue | C9: Queue sorts by outreach priority (overdue > never > scheduled > recent) | D9: Medium | E9: Functional | F9: Patients seeded with varied last_call_date values as per test data setup. | G9: 1. Open the Dial tab. 2. Inspect the order of the patient rows and their badges. | H9: Patients with last_call_date = none / today / 3 days ago / 8 days ago | I9: Rows are ordered so OVERDUE - 7D+ appears first, then NEVER CONTACTED, then SCHEDULED, then CONTACTED TODAY (client-side sort by getCallStatus priority {overdue:3, never:2, scheduled:1, recent:0}). | J9: N/A | L9: Not Executed
A10: CL-009 | B10: Dial - Outreach Queue | C10: Patient status badges render correctly for each call-recency bucket | D10: Medium | E10: UI/UX | F10: Patients seeded per CL-008. | G10: 1. Open the Dial tab. 2. Match each patient row's badge against its last_call_date. | H10: Same as CL-008 | I10: No last_call_date -> 'NEVER CONTACTED' (amber). <1 day -> 'CONTACTED TODAY' (emerald). 1-7 days -> 'SCHEDULED' (blue). >7 days -> 'OVERDUE - 7D+' (red, pulsing). Last Sync shows the formatted date or 'None'. | J10: N/A | L10: Not Executed
A11: CL-010 | B11: Dial - Outreach Queue | C11: Patient search filters the queue (debounced) by name | D11: High | E11: Functional | F11: Admin on Dial tab; patient 'Ramesh Kumar' exists. | G11: 1. Type 'Ramesh' into the 'Search patient or phone...' box. 2. Wait ~300ms and observe the Network tab and the list. | H11: Search term: Ramesh | I11: After the 300ms debounce a single GET /api/patients call fires with search=Ramesh; the list updates to matching patients. (Note: results are additionally filtered client-side by name/phone via sortedPatients.) | J11: GET /api/patients?search=Ramesh | L11: Not Executed
A12: CL-011 | B12: Dial - Outreach Queue | C12: Patient search by phone substring filters the visible rows | D12: Medium | E12: Functional | F12: Admin on Dial tab; a patient with phone +91 99000 11223 exists. | G12: 1. Type '99000' into the search box. 2. Observe the filtered rows. | H12: Search term: 99000 | I12: Rows are filtered to patients whose phone contains '99000' (client-side sortedPatients filter on p.phone). Non-matching rows are hidden. | J12: GET /api/patients?search=99000 | L12: Not Executed
A13: CL-012 | B13: Dial - Outreach Queue | C13: Outreach queue pagination Next/Previous navigates pages | D13: Medium | E13: Functional | F13: Admin on Dial tab; 12 patients (2 pages). | G13: 1. On page 1, click 'Next' in the queue footer. 2. Observe the list and footer. 3. Click 'Previous'. | H13: 12 patients, PER_PAGE 10 | I13: Next sets patientPage=2 -> GET /api/patients?page=2; footer reads 'Showing 11 to 12 of 12'; Next is disabled on the last page; Previous returns to page 1. | J13: GET /api/patients?page=2&per_page=10 | L13: Not Executed
... A85: CL-084 | B85: Data Integrity | C85: Tab data is scoped/loaded only for the active tab | D85: Low | E85: Data Integrity | F85: Admin on /call-logs; Network tab open. | G85: 1. Watch the Network tab while clicking through Dial -> History -> Escalated -> Scheduler. 2. Confirm which fetches fire per tab. | H85: N/A | I85: Dial fetches patients + agents; History (calls sub-tab) fetches exotel/calls; History (docs sub-tab) fetches sop/history; Escalated fetches exotel/sop; Scheduler fetches exotel/scheduler. Inactive-tab fetches are guarded (return early) so they do not fire. | J85: Multiple (see endpoints table) | L85: Not Executed

Sheet Users
A1: Test Case ID | B1: Section / Feature | C1: Test Title | D1: Priority | E1: Type | F1: Preconditions | G1: Test Steps | H1: Test Data | I1: Expected Result | J1: API Reference | K1: Actual Result | L1: Status | M1: Severity | N1: Tested By | O1: Date Tested | P1: Remarks / Defect ID
A2: USR-001 | B2: Permission & Access | C2: Admin can open the Users screen and see the Users sidebar item | D2: High | E2: Permission | F2: Logged in as admin_qa@saranam.in (role=admin). | G2: 1. Log in as the admin. 2. Observe the left sidebar navigation. 3. Click the 'Users' item. 4. Confirm the URL is /users and the Users list screen renders. | H2: admin_qa@saranam.in / Admin@123 | I2: The 'Users' item is visible in the sidebar. Clicking it routes to /users and renders the Users screen (title 'Users', subtitle 'Manage user accounts and permissions', filter card, users table). No 'Access Denied'. | J2: GET /api/users | L2: Not Executed
A3: USR-002 | B3: Permission & Access | C3: Data-entry user is blocked from /users and the sidebar item is hidden | D3: High | E3: Permission | F3: Logged in as rajesh.kumar@saranam.in (role=data_entry, approved+active). | G3: 1. Log in as the data_entry user. 2. Confirm the sidebar does NOT show a 'Users' item. 3. Manually navigate to /users via the address bar. 4. Observe the page. | H3: rajesh.kumar@saranam.in / Data@1234 | I3: No 'Users' item in sidebar (filtered out because data_entry lacks manage_users). Navigating to /users shows the 'Access Denied — You don't have permission to access this page.' panel (ProtectedRoute requiredRole='admin'); the users table is NOT rendered. | J3: N/A | L3: Not Executed
A4: USR-003 | B4: Permission & Access | C4: Viewer user is blocked from /users and the sidebar item is hidden | D4: High | E4: Permission | F4: Logged in as anjali.nair@saranam.in (role=viewer). | G4: 1. Log in as the viewer user. 2. Confirm no 'Users' item in the sidebar. 3. Navigate directly to /users. 4. Observe the result. | H4: anjali.nair@saranam.in / View@1234 | I4: Sidebar has no 'Users' item; /users shows 'Access Denied'. Viewer cannot reach the users table. | J4: N/A | L4: Not Executed
A5: USR-004 | B5: Permission & Access | C5: Unauthenticated visit to /users redirects to login | D5: High | E5: Permission | F5: Not logged in (clear localStorage / open a fresh private window). | G5: 1. Without logging in, enter https://saranam.fieldintel.ai/users in the address bar. 2. Observe redirect behaviour. | H5: N/A | I5: ProtectedRoute sees no user and redirects to /login (replace). No users data is fetched or shown. | J5: N/A | L5: Not Executed
A6: USR-005 | B6: Permission & Access | C6: API rejects a non-admin token with 403 for every Users endpoint | D6: High | E6: API | F6: Have a valid access_token for the data_entry user (capture from login response). | G6: 1. Using the data_entry token, call GET /api/users. 2. Call GET /api/users/pending/count. 3. Call PUT /api/users/{anyId}/toggle-status. 4. Inspect status codes and bodies. | H6: Authorization: Bearer <data_entry token> | I6: Each call returns HTTP 403 with body message 'Access denied. Required permission: manage_users' and error 'insufficient_permissions'. No data is returned or mutated. | J6: GET /api/users, GET /api/users/pending/count, PUT /api/users/{id}/toggle-status | L6: Not Executed
A7: USR-006 | B7: Permission & Access | C7: API rejects a missing/expired token with 401 | D7: High | E7: API | F7: None. | G7: 1. Call GET /api/users with NO Authorization header. 2. Call GET /api/users with an obviously invalid/expired Bearer token. 3. Inspect status codes. | H7: Authorization: (none) and Authorization: Bearer invalid.token.value | I7: Both calls return HTTP 401 (JWT verification fails). In the browser, the axios response interceptor attempts a refresh; if refresh_token is absent/invalid it clears storage and redirects to /login. | J7: GET /api/users | L7: Not Executed
A8: USR-007 | B8: Permission & Access | C8: Enumerate role capabilities on the Users module (matrix) | D8: Medium | E8: Permission | F8: Accounts for admin, data_entry, viewer available. | G8: 1. Log in as admin; confirm full Users access (list/approve/reject/edit/toggle). 2. Log in as data_entry; confirm zero Users access (no sidebar item, /users denied, API 403). 3. Log in as viewer; confirm zero Users access (no sidebar item, /users denied, API 403). | H8: Three role accounts from setup | I8: Only admin can list and manage users. data_entry and viewer have no access on UI or API. Matches permission map where only admin holds manage_users. | J8: GET /api/users | L8: Not Executed
A9: USR-008 | B9: Users List | C9: Loading skeleton appears while users are being fetched | D9: Medium | E9: UI/UX | F9: Admin logged in; throttle network (DevTools 'Slow 3G') to observe. | G9: 1. Throttle the network in DevTools. 2. Navigate to /users (or reload). 3. Observe the area where the table renders before data arrives. | H9: N/A | I9: While loading, a card with five grey animate-pulse skeleton bars is shown (no table, no empty state). After GET /api/users resolves, the skeleton is replaced by the table. | J9: GET /api/users | L9: Not Executed
A10: USR-009 | B10: Users List | C10: Users list loads and rows display name, email, role, status, joined date | D10: High | E10: Functional | F10: Admin logged in; >=12 users seeded. | G10: 1. Open /users. 2. Inspect the table columns: User, Role, Status, Joined, Actions. 3. Verify each row shows full_name (bold) over email (muted), a role badge, a status badge, and the created_at date. 4. Cross-check a row against the GET /api/users response payload. | H10: N/A | I10: Table renders all users. Each row: name+email in User cell; role badge with capitalised label and underscore replaced by space (e.g. 'data_entry' -> 'Data entry'); status badge; Joined = new Date(created_at).toLocaleDateString(); Actions per status. Data matches API. | J10: GET /api/users | L10: Not Executed
A11: USR-010 | B11: Users List | C11: Role badge colour mapping (admin=danger, data_entry=primary, viewer=gray) | D11: Low | E11: UI/UX | F11: Admin logged in; at least one user of each role present. | G11: 1. Open /users. 2. Locate an admin row, a data_entry row, and a viewer row. 3. Compare the colour of each role badge. | H11: N/A | I11: admin -> badge-danger (red), data_entry -> badge-primary, viewer -> badge-gray. Any unknown role would also render gray (default). | J11: N/A | L11: Not Executed
A12: USR-011 | B12: Users List | C12: Status badge mapping reflects approval and active flags | D12: High | E12: Functional | F12: Admin logged in; one pending, one active, one deactivated user present. | G12: 1. Open /users. 2. Find the pending user (is_approved=false). 3. Find the active user (is_approved=true, is_active=true). 4. Find the deactivated user (is_approved=true, is_active=false). 5. Verify the status badge for each. | H12: priya.menon (pending), rajesh.kumar (active), meena.raman (deactivated) | I12: Pending -> amber 'Pending Approval'; Active -> green 'Active'; Deactivated -> grey 'Inactive'. Note: precedence is approval first — any user with is_approved=false shows 'Pending Approval' even if inactive (see USR-031 data-integrity edge). | J12: N/A | L12: Not Executed
A13: USR-012 | B13: Users List | C13: Header shows the pending-approval count badge | D13: Medium | E13: Functional | F13: Admin logged in; exactly N users with is_approved=false (e.g. 2). | G13: 1. Open /users. 2. Observe the amber badge next to the 'Users' title. 3. Count the rows whose status is 'Pending Approval' and compare. | H13: Seed 2 unapproved users | I13: Header shows 'N pending approval' where N = count of users with is_approved=false. Badge is hidden when N=0. (Counted client-side from the loaded list, not from /pending/count.) | J13: N/A | L13: Not Executed
... A53: USR-052 | B53: Build / Coverage Gaps | C53: No admin-initiated Create User and no phone field on Users screen | D53: Medium | E53: Edge Case | F53: Admin logged in on /users. | G53: 1. Inspect the Users screen for any 'Add User' / 'Create User' / 'Invite' control. 2. Open the Edit modal and inspect for a phone (+91) field or password/reset control. 3. Confirm the only path to create a user is public self-registration at /register. | H53: N/A | I53: FINDING: there is NO Create/Add-User button on /users — new users can only self-register at /register (then be approved). The Edit modal has NO phone, NO status toggle, NO password/temp-password controls. Confirm with the client whether admin-side user creation and phone capture are required for go-live; otherwise mark these as known scope gaps. | J53: N/A | L53: Not Executed

Sheet Settings
A1: Test Case ID | B1: Section / Feature | C1: Test Title | D1: Priority | E1: Type | F1: Preconditions | G1: Test Steps | H1: Test Data | I1: Expected Result | J1: API Reference | K1: Actual Result | L1: Status | M1: Severity | N1: Tested By | O1: Date Tested | P1: Remarks / Defect ID
A2: SET-001 | B2: Page Load & Rendering | C2: Settings page loads with header and all five preference sections | D2: High | E2: Functional | F2: Logged in as any authenticated user. | G2: 1. Navigate to /settings (via sidebar 'Settings' link or direct URL). 2. Observe the page header and the list of cards top to bottom. | H2: N/A | I2: Page renders with no errors/blank screen. Header shows title 'Settings' and subtitle 'Manage your application preferences and appearance'. Exactly five cards render in order: Appearance, Typography, Border Radius, Density, Accessibility. The content is centred in a max-width container (max-w-4xl). | J2: N/A | L2: Not Executed
A3: SET-002 | B3: Page Load & Rendering | C3: Each section displays its correct title, icon and description | D3: Medium | E3: UI/UX | F3: On /settings. | G3: 1. Read each card's header. 2. Confirm titles, icons and descriptions. | H3: N/A | I3: Appearance: 'Customize how the dashboard looks on your device'. Typography (Type icon): 'Choose the font family for the application'. Border Radius (Square icon): 'Adjust the roundness of UI elements'. Density (Layers icon): 'Control the spacing and padding of UI elements'. Accessibility (Accessibility icon): 'Customize accessibility features for better usability'. No icons/text missing or overlapping. | J3: N/A | L3: Not Executed
